Workbook

Sheet Orçamentos
A1: CLIENTE | B1: RESPONSÁVEL | C1: PROJETO | D1: VALOR TOTAL | E1: DATA | F1: Processos | G1: LINK DO PDF | H1: LINK DA MEMÓRIA DE CÁLCULO | I1: STATUS
A2: Furnax Comercial Importadora | B2: ISMAEL | C2: 251013cBR | D2: 150.54124 | E2: 45943 | F2: Corte: 0.57h | Dobra: 3h | G2: https://drive.google.com/file/d/1aoVY-BuHHmbQQ1LWa_O57-LMl2rcGtQ-/view?usp=drivesdk | H2: https://drive.google.com/file/d/1xTtjTVpHedMfNbGRcd6gWF_3w3gi9ncr/view?usp=drivesdk | I2: Enviado
A3: TECNIGRAV INDUSTRIA E COMERCIO LTDA | B3: Rodrigo | C3: 251013dBR | D3: 1319.6586 | E3: 45943 | F3: Corte: 0.73h | Dobra: 2h | G3: https://drive.google.com/file/d/16P5hEEtPvtorQx97sG9lmJHGIzvFYyJA/view?usp=drivesdk | H3: https://drive.google.com/file/d/1_M51LSDFqNROTN0L3_yTKTCU3p7f7VQO/view?usp=drivesdk | I3: Enviado
A4: VANESSA BERTUCCI ENGENHARIA | B4: Vanessa | C4: 251016eBR | D4: 296.32954 | E4: 45964 | F4: Corte: 0.08h, Dobra: 0.20h, Adicionais: 0.50h | G4: https://drive.google.com/file/d/1DR0aD3_fFQcPmE8fVCSjP2MQaAaJHlMH/view?usp=drivesdk | H4: https://drive.google.com/file/d/1WQhiLQ1D3Nt52lR0Y0SLoCBOKDaFBuyt/view?usp=drivesdk | I4: Enviado
A5: ON CONVEYORS ESTEIRAS METALICAS INDUSTRIA E COMERCIO LTDA | C5: 251028cBR | D5: 396.03137 | E5: 45958 | G5: https://drive.google.com/file/d/1pwfjrWsybv8CzblsgMAPVxu2DG_TR5RB/view?usp=drivesdk | H5: https://drive.google.com/file/d/1NE3kKCzOaLcb_wM_g--gCaF5qKTboE8o/view?usp=drivesdk | I5: Enviado
A6: THERMAM LTDA | C6: 251014cBR | E6: 45944 | I6: Enviado
A7: MAX FIRE | C7: 250821dBR | E7: 45890 | G7: https://n-isnivimkqx3cchzjxhfuetumeft5hyp5rj7e3ui-0lu-script.googleusercontent.com/userCodeAppPanel | H7: https://n-isnivimkqx3cchzjxhfuetumeft5hyp5rj7e3ui-0lu-script.googleusercontent.com/userCodeAppPanel | I7: Rascunho
A8: LUSITÂNA | C8: 251105cBR | E8: 45966 | I8: Rascunho

Sheet Pedidos
A1: Cliente | B1: Número do Projeto | C1: Status | D1: Observações | E1: Tempo estimado por processo
A2: THERMAM LTDA | B2: 251014cBR | C2: Processo de Corte | E2: Corte: 5h | Dobra:
A3: VETTORE INDUSTRIA E COMERCIO LTDA | B3: 251031aMS | C3: Processo de Corte | E3: Corte: | Dobra:
A4: TECH ASSIST NETWORKING INDUSTRIA E COMERCIO, ASSISTENCIA TEC | B4: 251031dMS | C4: Envio / Coleta | E4: Corte: | Dobra:
A5: MAX FIRE EQUIPAMENTOS INDUSTRIAIS LTDA | B5: 251031eMS | C5: Finalizado | E5: Corte: | Dobra:
A6: FURNAX COMERCIAL E IMPORTADORA LTDA | B6: 251031fMS | C6: Finalizado | E6: Corte: | Dobra:
A7: D D EQUIPAMENTOS INDUSTRIAIS LTDA | B7: 251031gMS | C7: Finalizado | E7: Corte: | Dobra:
A8: THALLYS HENRIQUE ANDRADE LOURENCO - COMERCIO DE FERROS E FER | B8: 251103aMS | C8: Finalizado | E8: Corte: 0.7h | Dobra:
A9: ADRIANO DOS SANTOS DE SOUZA | B9: 251013fMS | C9: Processo de Corte | E9: Corte: | Dobra:
A10: HENRY PEÇAS COMÉRCIO E SERVIÇOS DE EQUIPAMENTOS HIDRÁULICOS | B10: 251104cBR | C10: Processo de Corte | E10: Corte: | Dobra:

Sheet Produtos
A1: Cliente | B1: Código | C1: Data | D1: Informações do Produto

Sheet Registro de Manutenções
A1: PLANO DE MANUTENÇÃO | B1: DATA/HORA | C1: RESPONSÁVEL | D1: FREQUÊNCIA | E1: COMPONENTE | F1: AÇÃO | G1: RESPONSÁVEL SUGERIDO
A2: Máquina Laser | B2: 45947.5 | C2: Bruno Macedo | D2: MENSAL | E2: Sistema de Resfriamento (Chiller) | F2: Troca do Fluido e Limpeza do Circuito | G2: Operador
A3: Máquina Laser | B3: 45947.5 | C3: Bruno Macedo | D3: MENSAL | E3: Guias Lineares Longitudinais | F3: Limpeza e Lubrificação | G3: Operador / Técnico
A4: Máquina Laser | B4: 45954.396 | C4: Matheus Rodrigues | D4: DIÁRIA | E4: Compressor | F4: Verificação de reservatório (purgar água) | G4: Operador
A5: Máquina Laser | B5: 45954.396 | C5: Matheus Rodrigues | D5: DIÁRIA | E5: Sistema de Resfriamento (Chiller) | F5: Monitoramento da Temperatura Ambiente | G5: Operador
A6: Máquina Laser | B6: 45961.375 | C6: Bruno Sena | D6: DIÁRIA | E6: Cabeça de Saída do Laser (Óptica) | F6: Inspeção Visual da Lente/bico de corte | G6: Operador
A7: Máquina Laser | B7: 45961.375 | C7: Bruno Sena | D7: DIÁRIA | E7: Compressor | F7: Verificação de reservatório (purgar água) | G7: Operador
A8: Máquina Laser | B8: 45961.375 | C8: Bruno Sena | D8: DIÁRIA | E8: Sistema de Resfriamento (Chiller) | F8: Monitoramento da Temperatura Ambiente | G8: Operador

Sheet Controle de Materiais
A1: Nº da Chapa | B1: DATA | C1: FEITO POR | D1: PROP | E1: TIPO | F1: DIM | G1: ESPESSURA | H1: MATERIAL | I1: QTDE | J1: FORNECEDOR | K1: NF | L1: CÓDIGO CHAPA | M1: ETIQUETA | N1: PESO APROXIMADO
A2: 16 | B2: 45918 | C2: Matheus Rodrigues | D2: TECH ASSIST | E2: Int. | F2: 1500 x 3000 | G2: 6 | H2: AÇO NÃO QUALIFICADO | I2: 8 | J2: ACERLOR MITTAL | M2: https://drive.google.com/file/d/1xGDdo1elMfZ3HqYBYx3HOhaa4Eyt8DSp/view?usp=drivesdk | N2: =IFERROR(__xludf.DUMMYFUNCTION("IF(OR(F2="""",G2="""",H2="""",I2=""""),"""", (VALUE(INDEX(SPLIT(REGEXREPLACE(F2,""[^\d]+"",""x""),""x""),1))/1000) * (VALUE(INDEX(SPLIT(REGEXREPLACE(F2,""[^\d]+"",""x""),""x""),2))/1000) * G2 * IF(REGEXMATCH(UPPER(H2),""AÇO|ACO""), 7.86, IF(REGEXMATCH(UPP"&"ER(H2),""ALUM""), 2.7, IF(REGEXMATCH(UPPER(H2),""LAT""), 8.73, IF(REGEXMATCH(UPPER(H2),""COBRE""), 8.96, 0) ) ) ) * I2 )"),1697.76) -> 1697.76
A3: 17 | B3: 45918 | C3: Matheus Rodrigues | D3: TECH ASSIST | E3: Retalho | F3: 1200 x 1800 | G3: 6.3 | H3: AÇO NÃO QUALIFICADO | I3: 1 | J3: TECH ASSIST | K3: 14991 | M3: https://drive.google.com/file/d/1JR7XI7Db9_2Z-SnKJSiJf-dil0wY_n1-/view?usp=drivesdk | N3: =IFERROR(__xludf.DUMMYFUNCTION("IF(OR(F3="""",G3="""",H3="""",I3=""""),"""", (VALUE(INDEX(SPLIT(REGEXREPLACE(F3,""[^\d]+"",""x""),""x""),1))/1000) * (VALUE(INDEX(SPLIT(REGEXREPLACE(F3,""[^\d]+"",""x""),""x""),2))/1000) * G3 * IF(REGEXMATCH(UPPER(H3),""AÇO|ACO""), 7.86, IF(REGEXMATCH(UPP"&"ER(H3),""ALUM""), 2.7, IF(REGEXMATCH(UPPER(H3),""LAT""), 8.73, IF(REGEXMATCH(UPPER(H3),""COBRE""), 8.96, 0) ) ) ) * I3 )"),106.95888) -> 106.95888
A4: 18 | B4: 45918 | C4: Matheus Rodrigues | D4: TECH ASSIST | E4: Int. | F4: 1200 x 3000 | G4: 1 | H4: AÇO NÃO QUALIFICADO | I4: 1 | J4: TECH ASSIST | K4: 14527 | L4: SAE1008 | M4: https://drive.google.com/file/d/1QWpXzdq4Zz-Rrxog2JSmECcfV5YJ5Y5L/view?usp=drivesdk | N4: =IFERROR(__xludf.DUMMYFUNCTION("IF(OR(F4="""",G4="""",H4="""",I4=""""),"""", (VALUE(INDEX(SPLIT(REGEXREPLACE(F4,""[^\d]+"",""x""),""x""),1))/1000) * (VALUE(INDEX(SPLIT(REGEXREPLACE(F4,""[^\d]+"",""x""),""x""),2))/1000) * G4 * IF(REGEXMATCH(UPPER(H4),""AÇO|ACO""), 7.86, IF(REGEXMATCH(UPP"&"ER(H4),""ALUM""), 2.7, IF(REGEXMATCH(UPPER(H4),""LAT""), 8.73, IF(REGEXMATCH(UPPER(H4),""COBRE""), 8.96, 0) ) ) ) * I4 )"),28.296) -> 28.296
A5: 19 | B5: 45918 | C5: Matheus Rodrigues | D5: TECH ASSIST | E5: Retalho | F5: 960 x 1200 | G5: 3 | H5: AÇO NÃO QUALIFICADO | I5: 1 | J5: TECH ASSIST | K5: 14527 | M5: https://drive.google.com/file/d/1rYvmjGy-SSXwRJoAe3KA0h6ZH3IKrcGy/view?usp=drivesdk | N5: =IFERROR(__xludf.DUMMYFUNCTION("IF(OR(F5="""",G5="""",H5="""",I5=""""),"""", (VALUE(INDEX(SPLIT(REGEXREPLACE(F5,""[^\d]+"",""x""),""x""),1))/1000) * (VALUE(INDEX(SPLIT(REGEXREPLACE(F5,""[^\d]+"",""x""),""x""),2))/1000) * G5 * IF(REGEXMATCH(UPPER(H5),""AÇO|ACO""), 7.86, IF(REGEXMATCH(UPP"&"ER(H5),""ALUM""), 2.7, IF(REGEXMATCH(UPPER(H5),""LAT""), 8.73, IF(REGEXMATCH(UPPER(H5),""COBRE""), 8.96, 0) ) ) ) * I5 )"),27.16416) -> 27.16416
A6: 20 | B6: 45918 | C6: Matheus Rodrigues | D6: TECH ASSIST | E6: Retalho | F6: 200 x 2380 | G6: 2 | H6: AÇO NÃO QUALIFICADO | I6: 1 | J6: TECH ASSIST | K6: 15567 | M6: https://drive.google.com/file/d/11Ti1nwZNPgV9LBeIntPHN_KH5KowsSwr/view?usp=drivesdk | N6: =IFERROR(__xludf.DUMMYFUNCTION("IF(OR(F6="""",G6="""",H6="""",I6=""""),"""", (VALUE(INDEX(SPLIT(REGEXREPLACE(F6,""[^\d]+"",""x""),""x""),1))/1000) * (VALUE(INDEX(SPLIT(REGEXREPLACE(F6,""[^\d]+"",""x""),""x""),2))/1000) * G6 * IF(REGEXMATCH(UPPER(H6),""AÇO|ACO""), 7.86, IF(REGEXMATCH(UPP"&"ER(H6),""ALUM""), 2.7, IF(REGEXMATCH(UPPER(H6),""LAT""), 8.73, IF(REGEXMATCH(UPPER(H6),""COBRE""), 8.96, 0) ) ) ) * I6 )"),7.48272) -> 7.48272
A7: 21 | B7: 45918 | C7: Matheus Rodrigues | D7: TECH ASSIST | E7: Int. | F7: 1200 x 2900 | G7: 1.5 | H7: AÇO NÃO QUALIFICADO | I7: 1 | J7: TECH ASSIST | K7: 15623 | L7: SAE120 | M7: https://drive.google.com/file/d/1Z2xegwGfYyJbPCkNEtb6aEeBkTsOhbWi/view?usp=drivesdk | N7: =IFERROR(__xludf.DUMMYFUNCTION("IF(OR(F7="""",G7="""",H7="""",I7=""""),"""", (VALUE(INDEX(SPLIT(REGEXREPLACE(F7,""[^\d]+"",""x""),""x""),1))/1000) * (VALUE(INDEX(SPLIT(REGEXREPLACE(F7,""[^\d]+"",""x""),""x""),2))/1000) * G7 * IF(REGEXMATCH(UPPER(H7),""AÇO|ACO""), 7.86, IF(REGEXMATCH(UPP"&"ER(H7),""ALUM""), 2.7, IF(REGEXMATCH(UPPER(H7),""LAT""), 8.73, IF(REGEXMATCH(UPPER(H7),""COBRE""), 8.96, 0) ) ) ) * I7 )"),41.0292) -> 41.0292
A8: 27 | B8: 45918 | C8: Matheus Rodrigues | D8: MDURO | E8: Int. | F8: 1415 X 520 | G8: 4 | H8: AÇO NÃO QUALIFICADO | I8: 2 | J8: MDURO | L8: PROJETO 971 | M8: https://drive.google.com/file/d/15FWLsrfuheY-xdiisFXJlOMMPd4qee3L/view?usp=drivesdk | N8: =IFERROR(__xludf.DUMMYFUNCTION("IF(OR(F8="""",G8="""",H8="""",I8=""""),"""", (VALUE(INDEX(SPLIT(REGEXREPLACE(F8,""[^\d]+"",""x""),""x""),1))/1000) * (VALUE(INDEX(SPLIT(REGEXREPLACE(F8,""[^\d]+"",""x""),""x""),2))/1000) * G8 * IF(REGEXMATCH(UPPER(H8),""AÇO|ACO""), 7.86, IF(REGEXMATCH(UPP"&"ER(H8),""ALUM""), 2.7, IF(REGEXMATCH(UPPER(H8),""LAT""), 8.73, IF(REGEXMATCH(UPPER(H8),""COBRE""), 8.96, 0) ) ) ) * I8 )"),46.267104) -> 46.267104
A9: 28 | B9: 45918 | C9: Matheus Rodrigues | D9: INSTALL PRIME | E9: Int. | F9: 1200 x 3000 | G9: 2 | H9: AÇO GALVANIZADA | I9: 1 | J9: INSTALL PRIME | M9: https://drive.google.com/file/d/197gBJhEs7p74BTbYF1yDINY4dK0SbiSJ/view?usp=drivesdk | N9: =IFERROR(__xludf.DUMMYFUNCTION("IF(OR(F9="""",G9="""",H9="""",I9=""""),"""", (VALUE(INDEX(SPLIT(REGEXREPLACE(F9,""[^\d]+"",""x""),""x""),1))/1000) * (VALUE(INDEX(SPLIT(REGEXREPLACE(F9,""[^\d]+"",""x""),""x""),2))/1000) * G9 * IF(REGEXMATCH(UPPER(H9),""AÇO|ACO""), 7.86, IF(REGEXMATCH(UPP"&"ER(H9),""ALUM""), 2.7, IF(REGEXMATCH(UPPER(H9),""LAT""), 8.73, IF(REGEXMATCH(UPPER(H9),""COBRE""), 8.96, 0) ) ) ) * I9 )"),56.592) -> 56.592
A10: 34 | B10: 45924 | C10: Bruno Macedo | D10: TUBA FERRAMENTARIA | E10: Int. | F10: 3000 x 1200 | G10: 3 | H10: AÇO NÃO QUALIFICADO | I10: 1 | J10: SOUFER | K10: 342459 | M10: https://drive.google.com/file/d/1bdH3_UkuadPTTholZ0bDiJta3huW8xzi/view?usp=drivesdk | N10: =IFERROR(__xludf.DUMMYFUNCTION("IF(OR(F10="""",G10="""",H10="""",I10=""""),"""", (VALUE(INDEX(SPLIT(REGEXREPLACE(F10,""[^\d]+"",""x""),""x""),1))/1000) * (VALUE(INDEX(SPLIT(REGEXREPLACE(F10,""[^\d]+"",""x""),""x""),2))/1000) * G10 * IF(REGEXMATCH(UPPER(H10),""AÇO|ACO""), 7.86, IF(REGEXM"&"ATCH(UPPER(H10),""ALUM""), 2.7, IF(REGEXMATCH(UPPER(H10),""LAT""), 8.73, IF(REGEXMATCH(UPPER(H10),""COBRE""), 8.96, 0) ) ) ) * I10 )"),84.8879999999999) -> 84.888
A11: 41 | B11: 45931 | C11: Bruno Macedo | D11: TEC BUSWAY | E11: Int. | F11: 3000 x 1200 | G11: 1.2 | H11: AÇO GALVANIZADO | I11: 3 | J11: TEC BUSWAY | M11: https://drive.google.com/file/d/1ADKVRT7DYZ_DXN_qvWxhNkn-PXdvQd54/view?usp=drivesdk | N11: =IFERROR(__xludf.DUMMYFUNCTION("IF(OR(F11="""",G11="""",H11="""",I11=""""),"""",(VALUE(INDEX(SPLIT(REGEXREPLACE(F11,""[^\d]+"",""x""),""x""),1))/1000)*(VALUE(INDEX(SPLIT(REGEXREPLACE(F11,""[^\d]+"",""x""),""x""),2))/1000)*G11*IF(REGEXMATCH(UPPER(H11),""AÇO|ACO""),7.86,IF(REGEXMATCH(UPPE"&"R(H11),""ALUM""),2.7,IF(REGEXMATCH(UPPER(H11),""LAT""),8.73,IF(REGEXMATCH(UPPER(H11),""COBRE""),8.96,0))))*I11)"),101.8656) -> 101.8656
A12: 42 | B12: 45931 | C12: Matheus Rodrigues | D12: CAETANO SOLUÇÕES | E12: Retalho | F12: 1250 x 850 | G12: 1.7 | H12: AÇO INOX | I12: 1 | J12: CAETANO | M12: https://drive.google.com/file/d/1kHQA556Kdl97G_b1l-XlqmCKeCvyro4b/view?usp=drivesdk | N12: =IFERROR(__xludf.DUMMYFUNCTION("IF(OR(F12="""",G12="""",H12="""",I12=""""),"""",(VALUE(INDEX(SPLIT(REGEXREPLACE(F12,""[^\d]+"",""x""),""x""),1))/1000)*(VALUE(INDEX(SPLIT(REGEXREPLACE(F12,""[^\d]+"",""x""),""x""),2))/1000)*G12*IF(REGEXMATCH(UPPER(H12),""AÇO|ACO""),7.86,IF(REGEXMATCH(UPPE"&"R(H12),""ALUM""),2.7,IF(REGEXMATCH(UPPER(H12),""LAT""),8.73,IF(REGEXMATCH(UPPER(H12),""COBRE""),8.96,0))))*I12)"),14.197125) -> 14.197125
A13: 43 | B13: 45931 | C13: Matheus Rodrigues | D13: CAETANO SOLUÇÕES | E13: Retalho | F13: 1285 x 820 | G13: 1.7 | H13: AÇO INOX | I13: 1 | J13: CAETANO | M13: https://drive.google.com/file/d/1rRVavZ62LS6GDbXfEcGUry5Wx3aBdYAG/view?usp=drivesdk | N13: =IFERROR(__xludf.DUMMYFUNCTION("IF(OR(F13="""",G13="""",H13="""",I13=""""),"""",(VALUE(INDEX(SPLIT(REGEXREPLACE(F13,""[^\d]+"",""x""),""x""),1))/1000)*(VALUE(INDEX(SPLIT(REGEXREPLACE(F13,""[^\d]+"",""x""),""x""),2))/1000)*G13*IF(REGEXMATCH(UPPER(H13),""AÇO|ACO""),7.86,IF(REGEXMATCH(UPPE"&"R(H13),""ALUM""),2.7,IF(REGEXMATCH(UPPER(H13),""LAT""),8.73,IF(REGEXMATCH(UPPER(H13),""COBRE""),8.96,0))))*I13)"),14.0795393999999) -> 14.079539
A14: 44 | B14: 45931 | C14: Matheus Rodrigues | D14: CAETANO SOLUÇÕES | E14: Retalho | F14: 1490 x 770 | G14: 1.7 | H14: AÇO INOX | I14: 1 | J14: CAETANO | M14: https://drive.google.com/file/d/1DzxFJC-41risALT-_yesN6r3Br6u-XIO/view?usp=drivesdk | N14: =IFERROR(__xludf.DUMMYFUNCTION("IF(OR(F14="""",G14="""",H14="""",I14=""""),"""",(VALUE(INDEX(SPLIT(REGEXREPLACE(F14,""[^\d]+"",""x""),""x""),1))/1000)*(VALUE(INDEX(SPLIT(REGEXREPLACE(F14,""[^\d]+"",""x""),""x""),2))/1000)*G14*IF(REGEXMATCH(UPPER(H14),""AÇO|ACO""),7.86,IF(REGEXMATCH(UPPE"&"R(H14),""ALUM""),2.7,IF(REGEXMATCH(UPPER(H14),""LAT""),8.73,IF(REGEXMATCH(UPPER(H14),""COBRE""),8.96,0))))*I14)"),15.3302226) -> 15.330223
A15: 45 | B15: 45931 | C15: Matheus Rodrigues | D15: TUBA FERRAMENTARIA | E15: Retalho | F15: 615 x 1215 | G15: 12.5 | H15: AÇO ASTM A36 | I15: 1 | J15: PIRES DO RIO | K15: 279012 | M15: https://drive.google.com/file/d/1mCiSL6JR-ZV7DuCfxy0xYLyHozkgXUgD/view?usp=drivesdk | N15: =IFERROR(__xludf.DUMMYFUNCTION("IF(OR(F15="""",G15="""",H15="""",I15=""""),"""",(VALUE(INDEX(SPLIT(REGEXREPLACE(F15,""[^\d]+"",""x""),""x""),1))/1000)*(VALUE(INDEX(SPLIT(REGEXREPLACE(F15,""[^\d]+"",""x""),""x""),2))/1000)*G15*IF(REGEXMATCH(UPPER(H15),""AÇO|ACO""),7.86,IF(REGEXMATCH(UPPE"&"R(H15),""ALUM""),2.7,IF(REGEXMATCH(UPPER(H15),""LAT""),8.73,IF(REGEXMATCH(UPPER(H15),""COBRE""),8.96,0))))*I15)"),73.41485625) -> 73.414856
A16: 46 | B16: 45931 | C16: Matheus Rodrigues | D16: TECH ASSIST | E16: Retalho | F16: 970 x 1210 | G16: 6.35 | H16: AÇO ASTM A572-50 | I16: 1 | J16: TECH ASSIST | K16: 14991 | M16: https://drive.google.com/file/d/18wcYUMcagJYdgbbJJJZFj9Ds8V2akAKr/view?usp=drivesdk | N16: =IFERROR(__xludf.DUMMYFUNCTION("IF(OR(F16="""",G16="""",H16="""",I16=""""),"""",(VALUE(INDEX(SPLIT(REGEXREPLACE(F16,""[^\d]+"",""x""),""x""),1))/1000)*(VALUE(INDEX(SPLIT(REGEXREPLACE(F16,""[^\d]+"",""x""),""x""),2))/1000)*G16*IF(REGEXMATCH(UPPER(H16),""AÇO|ACO""),7.86,IF(REGEXMATCH(UPPE"&"R(H16),""ALUM""),2.7,IF(REGEXMATCH(UPPER(H16),""LAT""),8.73,IF(REGEXMATCH(UPPER(H16),""COBRE""),8.96,0))))*I16)"),58.5805407) -> 58.580541
A17: 47 | B17: 45931 | C17: Matheus Rodrigues | D17: TECH ASSIST | E17: Retalho | F17: 1750 x 1210 | G17: 12.7 | H17: AÇO NÃO QUALIFICADO | I17: 1 | J17: TECH ASSIST | K17: 15567 | M17: https://drive.google.com/file/d/1pItXxRpFri0pfWiVyzDgYDW1cA3brI5U/view?usp=drivesdk | N17: =IFERROR(__xludf.DUMMYFUNCTION("IF(OR(F17="""",G17="""",H17="""",I17=""""),"""",(VALUE(INDEX(SPLIT(REGEXREPLACE(F17,""[^\d]+"",""x""),""x""),1))/1000)*(VALUE(INDEX(SPLIT(REGEXREPLACE(F17,""[^\d]+"",""x""),""x""),2))/1000)*G17*IF(REGEXMATCH(UPPER(H17),""AÇO|ACO""),7.86,IF(REGEXMATCH(UPPE"&"R(H17),""ALUM""),2.7,IF(REGEXMATCH(UPPER(H17),""LAT""),8.73,IF(REGEXMATCH(UPPER(H17),""COBRE""),8.96,0))))*I17)"),211.373084999999) -> 211.37308
A18: 48 | B18: 45931 | C18: Matheus Rodrigues | D18: TECH ASSIST | E18: Retalho | F18: 1200 x 950 | G18: 1.5 | H18: AÇO NÃO QUALIFICADO | I18: 1 | J18: TECH ASSIST | M18: https://drive.google.com/file/d/1yrQ3wWNi7kcpMpfDERroZBqWw-Izbaa5/view?usp=drivesdk | N18: =IFERROR(__xludf.DUMMYFUNCTION("IF(OR(F18="""",G18="""",H18="""",I18=""""),"""",(VALUE(INDEX(SPLIT(REGEXREPLACE(F18,""[^\d]+"",""x""),""x""),1))/1000)*(VALUE(INDEX(SPLIT(REGEXREPLACE(F18,""[^\d]+"",""x""),""x""),2))/1000)*G18*IF(REGEXMATCH(UPPER(H18),""AÇO|ACO""),7.86,IF(REGEXMATCH(UPPE"&"R(H18),""ALUM""),2.7,IF(REGEXMATCH(UPPER(H18),""LAT""),8.73,IF(REGEXMATCH(UPPER(H18),""COBRE""),8.96,0))))*I18)"),13.4406) -> 13.4406
A19: 50 | B19: 45931 | C19: Matheus Rodrigues | D19: TUBA FERRAMENTARIA | E19: Retalho | F19: 700 x 1210 | G19: 9.5 | H19: AÇO ASTM A36 | I19: 1 | J19: SOUFER | K19: 358716 | L19: SAEJ4031010 | M19: https://drive.google.com/file/d/143mT54YOxH0uQBUaJ6_RGOeCair_jSik/view?usp=drivesdk | N19: =IFERROR(__xludf.DUMMYFUNCTION("IF(OR(F19="""",G19="""",H19="""",I19=""""),"""",(VALUE(INDEX(SPLIT(REGEXREPLACE(F19,""[^\d]+"",""x""),""x""),1))/1000)*(VALUE(INDEX(SPLIT(REGEXREPLACE(F19,""[^\d]+"",""x""),""x""),2))/1000)*G19*IF(REGEXMATCH(UPPER(H19),""AÇO|ACO""),7.86,IF(REGEXMATCH(UPPE"&"R(H19),""ALUM""),2.7,IF(REGEXMATCH(UPPER(H19),""LAT""),8.73,IF(REGEXMATCH(UPPER(H19),""COBRE""),8.96,0))))*I19)"),63.24549) -> 63.24549
A20: 52 | B20: 45931 | C20: Matheus Rodrigues | D20: TUBA FERRAMENTARIA | E20: Retalho | F20: 2445 x 215 | G20: 0.8 | H20: AÇO GALVAZINADA | I20: 1 | M20: https://drive.google.com/file/d/1lFfXyhlqR0CcoYQ749UqelZBdlB8ZRcs/view?usp=drivesdk | N20: =IFERROR(__xludf.DUMMYFUNCTION("IF(OR(F20="""",G20="""",H20="""",I20=""""),"""",(VALUE(INDEX(SPLIT(REGEXREPLACE(F20,""[^\d]+"",""x""),""x""),1))/1000)*(VALUE(INDEX(SPLIT(REGEXREPLACE(F20,""[^\d]+"",""x""),""x""),2))/1000)*G20*IF(REGEXMATCH(UPPER(H20),""AÇO|ACO""),7.86,IF(REGEXMATCH(UPPE"&"R(H20),""ALUM""),2.7,IF(REGEXMATCH(UPPER(H20),""LAT""),8.73,IF(REGEXMATCH(UPPER(H20),""COBRE""),8.96,0))))*I20)"),3.3054444) -> 3.3054444
A21: 53 | B21: 45931 | C21: Matheus Rodrigues | D21: TUBA FERRAMENTARIA | E21: Retalho | F21: 1205 x 565 | G21: 0.8 | H21: AÇO GALVAZINADA | I21: 1 | M21: https://drive.google.com/file/d/1q7nnEeewBj0JnzQbaDgmf-fNzz03UdY2/view?usp=drivesdk | N21: =IFERROR(__xludf.DUMMYFUNCTION("IF(OR(F21="""",G21="""",H21="""",I21=""""),"""",(VALUE(INDEX(SPLIT(REGEXREPLACE(F21,""[^\d]+"",""x""),""x""),1))/1000)*(VALUE(INDEX(SPLIT(REGEXREPLACE(F21,""[^\d]+"",""x""),""x""),2))/1000)*G21*IF(REGEXMATCH(UPPER(H21),""AÇO|ACO""),7.86,IF(REGEXMATCH(UPPE"&"R(H21),""ALUM""),2.7,IF(REGEXMATCH(UPPER(H21),""LAT""),8.73,IF(REGEXMATCH(UPPER(H21),""COBRE""),8.96,0))))*I21)"),4.2810276) -> 4.2810276
A22: 54 | B22: 45931 | C22: Matheus Rodrigues | D22: TUBA FERRAMENTARIA | E22: Retalho | F22: 1210 x 570 | G22: 0.8 | H22: AÇO GALVAZINADA | I22: 3 | M22: https://drive.google.com/file/d/14WrEWlJ_jBUXqsIL4E1dlhQj2P91yluk/view?usp=drivesdk | N22: =IFERROR(__xludf.DUMMYFUNCTION("IF(OR(F22="""",G22="""",H22="""",I22=""""),"""",(VALUE(INDEX(SPLIT(REGEXREPLACE(F22,""[^\d]+"",""x""),""x""),1))/1000)*(VALUE(INDEX(SPLIT(REGEXREPLACE(F22,""[^\d]+"",""x""),""x""),2))/1000)*G22*IF(REGEXMATCH(UPPER(H22),""AÇO|ACO""),7.86,IF(REGEXMATCH(UPPE"&"R(H22),""ALUM""),2.7,IF(REGEXMATCH(UPPER(H22),""LAT""),8.73,IF(REGEXMATCH(UPPER(H22),""COBRE""),8.96,0))))*I22)"),13.0105007999999) -> 13.010501
A23: 55 | B23: 45931 | C23: Matheus Rodrigues | D23: TUBA FERRAMENTARIA | E23: Retalho | F23: 2445 x 180 | G23: 0.8 | H23: AÇO GALVAZINADA | I23: 1 | M23: https://drive.google.com/file/d/14dcS4Fak3CMYr64XimOvP1X0D84H6hXV/view?usp=drivesdk | N23: =IFERROR(__xludf.DUMMYFUNCTION("IF(OR(F23="""",G23="""",H23="""",I23=""""),"""",(VALUE(INDEX(SPLIT(REGEXREPLACE(F23,""[^\d]+"",""x""),""x""),1))/1000)*(VALUE(INDEX(SPLIT(REGEXREPLACE(F23,""[^\d]+"",""x""),""x""),2))/1000)*G23*IF(REGEXMATCH(UPPER(H23),""AÇO|ACO""),7.86,IF(REGEXMATCH(UPPE"&"R(H23),""ALUM""),2.7,IF(REGEXMATCH(UPPER(H23),""LAT""),8.73,IF(REGEXMATCH(UPPER(H23),""COBRE""),8.96,0))))*I23)"),2.76734879999999) -> 2.7673488
A24: 56 | B24: 45932 | C24: Matheus Rodrigues | D24: MCMETAIS - LÉO | E24: Int. | F24: 3000 x 1200 | G24: 0.8 | H24: AÇO GALVANIZADO | I24: 180 | J24: MCMETAIS | M24: https://drive.google.com/file/d/1QZix3hlsRXoTTsqDgkjVpsYEa81L9EIh/view?usp=drivesdk | N24: =IFERROR(__xludf.DUMMYFUNCTION("IF(OR(F24="""",G24="""",H24="""",I24=""""),"""",(VALUE(INDEX(SPLIT(REGEXREPLACE(F24,""[^\d]+"",""x""),""x""),1))/1000)*(VALUE(INDEX(SPLIT(REGEXREPLACE(F24,""[^\d]+"",""x""),""x""),2))/1000)*G24*IF(REGEXMATCH(UPPER(H24),""AÇO|ACO""),7.86,IF(REGEXMATCH(UPPE"&"R(H24),""ALUM""),2.7,IF(REGEXMATCH(UPPER(H24),""LAT""),8.73,IF(REGEXMATCH(UPPER(H24),""COBRE""),8.96,0))))*I24)"),4074.624) -> 4074.624
A25: 57 | B25: 45932 | C25: Matheus Rodrigues | D25: TUBA FERRAMENTARIA | E25: Retalho | F25: 840 x 130 | G25: 5 | H25: AÇO NÃO QUALIFICADO | I25: 1 | M25: https://drive.google.com/file/d/1gXaEj38MYZdzR1N_OX3EsTYLTnnDBGDd/view?usp=drivesdk | N25: =IFERROR(__xludf.DUMMYFUNCTION("IF(OR(F25="""",G25="""",H25="""",I25=""""),"""",(VALUE(INDEX(SPLIT(REGEXREPLACE(F25,""[^\d]+"",""x""),""x""),1))/1000)*(VALUE(INDEX(SPLIT(REGEXREPLACE(F25,""[^\d]+"",""x""),""x""),2))/1000)*G25*IF(REGEXMATCH(UPPER(H25),""AÇO|ACO""),7.86,IF(REGEXMATCH(UPPE"&"R(H25),""ALUM""),2.7,IF(REGEXMATCH(UPPER(H25),""LAT""),8.73,IF(REGEXMATCH(UPPER(H25),""COBRE""),8.96,0))))*I25)"),4.29156) -> 4.29156
A26: 58 | B26: 45932 | C26: Matheus Rodrigues | D26: TUBA FERRAMENTARIA | E26: Retalho | F26: 3000 x 210 | G26: 5 | H26: AÇO NÃO QUALIFICADO | I26: 1 | M26: https://drive.google.com/file/d/10H10fab6afUrcjwpEl0M6NSKAcG4KX4j/view?usp=drivesdk | N26: =IFERROR(__xludf.DUMMYFUNCTION("IF(OR(F26="""",G26="""",H26="""",I26=""""),"""",(VALUE(INDEX(SPLIT(REGEXREPLACE(F26,""[^\d]+"",""x""),""x""),1))/1000)*(VALUE(INDEX(SPLIT(REGEXREPLACE(F26,""[^\d]+"",""x""),""x""),2))/1000)*G26*IF(REGEXMATCH(UPPER(H26),""AÇO|ACO""),7.86,IF(REGEXMATCH(UPPE"&"R(H26),""ALUM""),2.7,IF(REGEXMATCH(UPPER(H26),""LAT""),8.73,IF(REGEXMATCH(UPPER(H26),""COBRE""),8.96,0))))*I26)"),24.759) -> 24.759
A27: 59 | B27: 45932 | C27: Matheus Rodrigues | D27: TUBA FERRAMENTARIA | E27: Retalho | F27: 3000 x 120 | G27: 5 | H27: AÇO NÃO QUALIFICADO | I27: 1 | M27: https://drive.google.com/file/d/1ceqGAtUTK1AixcqCTXXSq4NARu_Rtemf/view?usp=drivesdk | N27: =IFERROR(__xludf.DUMMYFUNCTION("IF(OR(F27="""",G27="""",H27="""",I27=""""),"""",(VALUE(INDEX(SPLIT(REGEXREPLACE(F27,""[^\d]+"",""x""),""x""),1))/1000)*(VALUE(INDEX(SPLIT(REGEXREPLACE(F27,""[^\d]+"",""x""),""x""),2))/1000)*G27*IF(REGEXMATCH(UPPER(H27),""AÇO|ACO""),7.86,IF(REGEXMATCH(UPPE"&"R(H27),""ALUM""),2.7,IF(REGEXMATCH(UPPER(H27),""LAT""),8.73,IF(REGEXMATCH(UPPER(H27),""COBRE""),8.96,0))))*I27)"),14.148) -> 14.148
A28: 60 | B28: 45932 | C28: Matheus Rodrigues | D28: TUBA FERRAMENTARIA | E28: Retalho | F28: 3000 x 130 | G28: 5 | H28: AÇO NÃO QUALIFICADO | I28: 1 | M28: https://drive.google.com/file/d/1yMuIMOE1fX7oOhaPxgfVEBmNpGgMVjLI/view?usp=drivesdk | N28: =IFERROR(__xludf.DUMMYFUNCTION("IF(OR(F28="""",G28="""",H28="""",I28=""""),"""",(VALUE(INDEX(SPLIT(REGEXREPLACE(F28,""[^\d]+"",""x""),""x""),1))/1000)*(VALUE(INDEX(SPLIT(REGEXREPLACE(F28,""[^\d]+"",""x""),""x""),2))/1000)*G28*IF(REGEXMATCH(UPPER(H28),""AÇO|ACO""),7.86,IF(REGEXMATCH(UPPE"&"R(H28),""ALUM""),2.7,IF(REGEXMATCH(UPPER(H28),""LAT""),8.73,IF(REGEXMATCH(UPPER(H28),""COBRE""),8.96,0))))*I28)"),15.327) -> 15.327
A29: 61 | B29: 45932 | C29: Matheus Rodrigues | D29: TUBA FERRAMENTARIA | E29: Retalho | F29: 3000 x 90 | G29: 5 | H29: AÇO NÃO QUALIFICADO | I29: 1 | M29: https://drive.google.com/file/d/1ZYYzAOlViTQiJzvTBGxnRNG5NkWtYfHi/view?usp=drivesdk | N29: =IFERROR(__xludf.DUMMYFUNCTION("IF(OR(F29="""",G29="""",H29="""",I29=""""),"""",(VALUE(INDEX(SPLIT(REGEXREPLACE(F29,""[^\d]+"",""x""),""x""),1))/1000)*(VALUE(INDEX(SPLIT(REGEXREPLACE(F29,""[^\d]+"",""x""),""x""),2))/1000)*G29*IF(REGEXMATCH(UPPER(H29),""AÇO|ACO""),7.86,IF(REGEXMATCH(UPPE"&"R(H29),""ALUM""),2.7,IF(REGEXMATCH(UPPER(H29),""LAT""),8.73,IF(REGEXMATCH(UPPER(H29),""COBRE""),8.96,0))))*I29)"),10.611) -> 10.611
A30: 64 | B30: 45932 | C30: Matheus Rodrigues | D30: TECH ASSIST | E30: Retalho | F30: 420x 1210 | G30: 2.65 | H30: AÇO ASTM A572 | I30: 1 | J30: TECH ASSIST | K30: 14584 | M30: https://drive.google.com/file/d/16FzKhZvsfevHhxRAdBhZnLX1ULfl73nD/view?usp=drivesdk | N30: =IFERROR(__xludf.DUMMYFUNCTION("IF(OR(F30="""",G30="""",H30="""",I30=""""),"""",(VALUE(INDEX(SPLIT(REGEXREPLACE(F30,""[^\d]+"",""x""),""x""),1))/1000)*(VALUE(INDEX(SPLIT(REGEXREPLACE(F30,""[^\d]+"",""x""),""x""),2))/1000)*G30*IF(REGEXMATCH(UPPER(H30),""AÇO|ACO""),7.86,IF(REGEXMATCH(UPPE"&"R(H30),""ALUM""),2.7,IF(REGEXMATCH(UPPER(H30),""LAT""),8.73,IF(REGEXMATCH(UPPER(H30),""COBRE""),8.96,0))))*I30)"),10.5852978) -> 10.585298
A31: 65 | B31: 45932 | C31: Matheus Rodrigues | D31: TEC BUSWAY | E31: Retalho | F31: 700 x 1200 | G31: 2.6 | H31: AÇO NÃO QUALIFICADO | I31: 1 | J31: TECH ASSIST | K31: 8150 | M31: https://drive.google.com/file/d/1jO8akAsSessBlUmhVLJNHEqOS2NgqIS3/view?usp=drivesdk | N31: =IFERROR(__xludf.DUMMYFUNCTION("IF(OR(F31="""",G31="""",H31="""",I31=""""),"""",(VALUE(INDEX(SPLIT(REGEXREPLACE(F31,""[^\d]+"",""x""),""x""),1))/1000)*(VALUE(INDEX(SPLIT(REGEXREPLACE(F31,""[^\d]+"",""x""),""x""),2))/1000)*G31*IF(REGEXMATCH(UPPER(H31),""AÇO|ACO""),7.86,IF(REGEXMATCH(UPPE"&"R(H31),""ALUM""),2.7,IF(REGEXMATCH(UPPER(H31),""LAT""),8.73,IF(REGEXMATCH(UPPER(H31),""COBRE""),8.96,0))))*I31)"),17.16624) -> 17.16624
A32: 69 | B32: 45933 | C32: Matheus Rodrigues | D32: TUBA FERRAMENTARIA | E32: Retalho | F32: 680 x 1720 | G32: 1.5 | H32: AÇO NÃO QUALIFICADO | I32: 1 | M32: https://drive.google.com/file/d/1ieCTXMb-xYK6go8U50ZBHLpuCBDRCZDT/view?usp=drivesdk | N32: =IFERROR(__xludf.DUMMYFUNCTION("IF(OR(F32="""",G32="""",H32="""",I32=""""),"""",(VALUE(INDEX(SPLIT(REGEXREPLACE(F32,""[^\d]+"",""x""),""x""),1))/1000)*(VALUE(INDEX(SPLIT(REGEXREPLACE(F32,""[^\d]+"",""x""),""x""),2))/1000)*G32*IF(REGEXMATCH(UPPER(H32),""AÇO|ACO""),7.86,IF(REGEXMATCH(UPPE"&"R(H32),""ALUM""),2.7,IF(REGEXMATCH(UPPER(H32),""LAT""),8.73,IF(REGEXMATCH(UPPER(H32),""COBRE""),8.96,0))))*I32)"),13.789584) -> 13.789584
A33: 74 | B33: 45933 | C33: Matheus Rodrigues | D33: TUBA FERRAMENTARIA | E33: Retalho | F33: 1220 x 1200 | G33: 3 | H33: AÇO NÃO QUALIFICADO | I33: 1 | J33: ACERLOR MITTAL | M33: https://drive.google.com/file/d/17WyFHAfnb5DPjkttmj2McBeybTSMPAJw/view?usp=drivesdk | N33: =IFERROR(__xludf.DUMMYFUNCTION("IF(OR(F33="""",G33="""",H33="""",I33=""""),"""",(VALUE(INDEX(SPLIT(REGEXREPLACE(F33,""[^\d]+"",""x""),""x""),1))/1000)*(VALUE(INDEX(SPLIT(REGEXREPLACE(F33,""[^\d]+"",""x""),""x""),2))/1000)*G33*IF(REGEXMATCH(UPPER(H33),""AÇO|ACO""),7.86,IF(REGEXMATCH(UPPE"&"R(H33),""ALUM""),2.7,IF(REGEXMATCH(UPPER(H33),""LAT""),8.73,IF(REGEXMATCH(UPPER(H33),""COBRE""),8.96,0))))*I33)"),34.5211199999999) -> 34.52112
A34: 95 | B34: 45940 | C34: Bruno Macedo | D34: TUBA FERRAMENTARIA | E34: Int. | F34: 3000 x 1200 | G34: 4 | H34: AÇO INOX | I34: 1 | J34: SIANFER | K34: 178179 | L34: 2188 | M34: https://drive.google.com/file/d/1eCMbvlJg28Br3_i-xRnPYKtdQFgGpmVs/view?usp=drivesdk | N34: =IFERROR(__xludf.DUMMYFUNCTION("IF(OR(F34="""",G34="""",H34="""",I34=""""),"""",(VALUE(INDEX(SPLIT(REGEXREPLACE(F34,""[^\d]+"",""x""),""x""),1))/1000)*(VALUE(INDEX(SPLIT(REGEXREPLACE(F34,""[^\d]+"",""x""),""x""),2))/1000)*G34*IF(REGEXMATCH(UPPER(H34),""AÇO|ACO""),7.86,IF(REGEXMATCH(UPPE"&"R(H34),""ALUM""),2.7,IF(REGEXMATCH(UPPER(H34),""LAT""),8.73,IF(REGEXMATCH(UPPER(H34),""COBRE""),8.96,0))))*I34)"),113.184) -> 113.184
A35: 96 | B35: 45944 | C35: Matheus Rodrigues | D35: TUBA FERRAMENTARIA | E35: Int. | F35: 3000 x 1200 | G35: 3.75 | H35: AÇO ASTM A36 | I35: 2 | J35: PIRES DO RIO | K35: 286893 | L35: SAE 1008/1012 | M35: https://drive.google.com/file/d/1habhyQ7zVTDKJRePmUDnj3jJjlEvZYvp/view?usp=drivesdk | N35: =IFERROR(__xludf.DUMMYFUNCTION("IF(OR(F35="""",G35="""",H35="""",I35=""""),"""",(VALUE(INDEX(SPLIT(REGEXREPLACE(F35,""[^\d]+"",""x""),""x""),1))/1000)*(VALUE(INDEX(SPLIT(REGEXREPLACE(F35,""[^\d]+"",""x""),""x""),2))/1000)*G35*IF(REGEXMATCH(UPPER(H35),""AÇO|ACO""),7.86,IF(REGEXMATCH(UPPE"&"R(H35),""ALUM""),2.7,IF(REGEXMATCH(UPPER(H35),""LAT""),8.73,IF(REGEXMATCH(UPPER(H35),""COBRE""),8.96,0))))*I35)"),212.219999999999) -> 212.22
A36: 104 | B36: 45947 | C36: Matheus Rodrigues | D36: TUBA FERRAMENTARIA | E36: Int. | F36: 3000 x 1200 | G36: 9.5 | H36: AÇO ASTM A36 | I36: 1 | J36: MULTI METAIS | K36: 3042 | M36: https://drive.google.com/file/d/1rNAoJNt_9jC9KYSNjhTlWqER2SOOSW_s/view?usp=drivesdk | N36: =IFERROR(__xludf.DUMMYFUNCTION("IF(OR(F36="""",G36="""",H36="""",I36=""""),"""",(VALUE(INDEX(SPLIT(REGEXREPLACE(F36,""[^\d]+"",""x""),""x""),1))/1000)*(VALUE(INDEX(SPLIT(REGEXREPLACE(F36,""[^\d]+"",""x""),""x""),2))/1000)*G36*IF(REGEXMATCH(UPPER(H36),""AÇO|ACO""),7.86,IF(REGEXMATCH(UPPE"&"R(H36),""ALUM""),2.7,IF(REGEXMATCH(UPPER(H36),""LAT""),8.73,IF(REGEXMATCH(UPPER(H36),""COBRE""),8.96,0))))*I36)"),268.811999999999) -> 268.812
A37: 105 | B37: 45947 | C37: Matheus Rodrigues | D37: TUBA FERRAMENTARIA | E37: Inteiro | F37: 3000 x 1200 | G37: 12.7 | H37: AÇO ASTM A36 | I37: 2 | J37: MULTI METAIS | K37: 3042 | M37: https://drive.google.com/file/d/11tD4obh9MTiY01u_PpaRouSSEVQEHw2q/view?usp=drivesdk | N37: =IFERROR(__xludf.DUMMYFUNCTION("IF(OR(F37="""",G37="""",H37="""",I37=""""),"""",(VALUE(INDEX(SPLIT(REGEXREPLACE(F37,""[^\d]+"",""x""),""x""),1))/1000)*(VALUE(INDEX(SPLIT(REGEXREPLACE(F37,""[^\d]+"",""x""),""x""),2))/1000)*G37*IF(REGEXMATCH(UPPER(H37),""AÇO|ACO""),7.86,IF(REGEXMATCH(UPPE"&"R(H37),""ALUM""),2.7,IF(REGEXMATCH(UPPER(H37),""LAT""),8.73,IF(REGEXMATCH(UPPER(H37),""COBRE""),8.96,0))))*I37)"),718.718399999999) -> 718.7184
A38: 107 | B38: 45950 | C38: Bruno Macedo | D38: TUBA FERRAMENTARIA | E38: Int. | F38: 3000 x 1200 | G38: 2 | H38: AÇO ASTM A36 | I38: 5 | J38: MULTI METAIS | K38: 3042 | M38: https://drive.google.com/file/d/159ONApUSbBTpLf-D0XtaqewaiVxUcTro/view?usp=drivesdk | N38: =IFERROR(__xludf.DUMMYFUNCTION("IF(OR(F38="""",G38="""",H38="""",I38=""""),"""",(VALUE(INDEX(SPLIT(REGEXREPLACE(F38,""[^\d]+"",""x""),""x""),1))/1000)*(VALUE(INDEX(SPLIT(REGEXREPLACE(F38,""[^\d]+"",""x""),""x""),2))/1000)*G38*IF(REGEXMATCH(UPPER(H38),""AÇO|ACO""),7.86,IF(REGEXMATCH(UPPE"&"R(H38),""ALUM""),2.7,IF(REGEXMATCH(UPPER(H38),""LAT""),8.73,IF(REGEXMATCH(UPPER(H38),""COBRE""),8.96,0))))*I38)"),282.96) -> 282.96
A39: 112 | B39: 45957 | C39: Matheus Rodrigues | D39: TUBA FERRAMENTARIA | E39: Int. | F39: 3000 x 1200 | G39: 4.25 | H39: AÇO FF | I39: 2 | J39: MULTI METAIS | K39: 3086 | L39: SAE 1008 | M39: https://drive.google.com/file/d/1lDyo5KainNsi7_R6gUHiV9dcY0s9mU__/view?usp=drivesdk | N39: =IFERROR(__xludf.DUMMYFUNCTION("IF(OR(F39="""",G39="""",H39="""",I39=""""),"""",(VALUE(INDEX(SPLIT(REGEXREPLACE(F39,""[^\d]+"",""x""),""x""),1))/1000)*(VALUE(INDEX(SPLIT(REGEXREPLACE(F39,""[^\d]+"",""x""),""x""),2))/1000)*G39*IF(REGEXMATCH(UPPER(H39),""AÇO|ACO""),7.86,IF(REGEXMATCH(UPPE"&"R(H39),""ALUM""),2.7,IF(REGEXMATCH(UPPER(H39),""LAT""),8.73,IF(REGEXMATCH(UPPER(H39),""COBRE""),8.96,0))))*I39)"),240.516) -> 240.516
A40: 114 | B40: 45958 | C40: Bruno Sena | D40: Joalmi | E40: Int. | F40: 2000 x 222 | G40: 2 | H40: AÇO IAPO1000 | I40: 46 | J40: Joelmi | K40: 258796 | L40: 52249799 | M40: https://drive.google.com/file/d/1bQTc9ArM96daiejCKqbsEtMG5DjqsHve/view?usp=drivesdk | N40: =IFERROR(__xludf.DUMMYFUNCTION("IF(OR(F40="""",G40="""",H40="""",I40=""""),"""",(VALUE(INDEX(SPLIT(REGEXREPLACE(F40,""[^\d]+"",""x""),""x""),1))/1000)*(VALUE(INDEX(SPLIT(REGEXREPLACE(F40,""[^\d]+"",""x""),""x""),2))/1000)*G40*IF(REGEXMATCH(UPPER(H40),""AÇO|ACO""),7.86,IF(REGEXMATCH(UPPE"&"R(H40),""ALUM""),2.7,IF(REGEXMATCH(UPPER(H40),""LAT""),8.73,IF(REGEXMATCH(UPPER(H40),""COBRE""),8.96,0))))*I40)"),321.06528) -> 321.06528
...

Sheet Cadastro de Clientes
A1: CLIENTE | B1: CPF/CNPJ | C1: ENDEREÇO | D1: TELEFONE | E1: EMAIL
A2: KORG CAMPING E NÁUTICA INDÚSTRIA E COMÉRCIO LTDA | B2: 58.227.182/0001-18 | C2: Via Anchieta, 742 - Ipiranga - São Paulo - SP CEP: 04246-000 | D2: (11) 2272-0752 | E2: korg@korgcarretas.com.br
A3: TEC BUSWAY ENGENHARIA E INSTALAÇÕES LTDA | B3: 57.954.847/0001-22 | C3: Rua Graciosa Trevisan Salvatori, 76 - Nova vinhedo - Valinhos - SP - CEP: 13284-140 | D3: (19) 9759-2002 | E3: doriventura@yahoo.com.br
A4: HOME CÃO SERVIÇOS MÉDICOS VETERINARIOS LTDA | B4: 27.939.911/0001-35 | C4: Estrada dos Alvarengas, 410 LETRA B - Assunção, São Bernardo do Campo - SP CEP: 098550-550 | D4: (11) 8134-2093 | E4: kiriamartinez@ig.com.br
A5: APLITECNO INDUSTRIA E COMERCIO LTDA | B5: 24.384.654/0001-24 | C5: Avenida Pedro Roschel Gottzfritz, 284 - Terceira Divisao de Interlagos, Sao Paulo - SP, 04809-160 | D5: (11) 5510-9609 | E5: atlas_ofc@uol.com.br
A6: TECNIGRAV INDUSTRIA E COMERCIO LTDA | B6: 60.326.501/0001-94 | C6: Av. Álvaro Guimarães, 724 - Planalto, São Bernardo do Campo - SP, 09890-003 | D6: (11) 3465-5000 | E6: cris@tecnigrav.com
A7: SEBASTIAN PARAIBA
A8: PRIMORDIAL REFORMA DE CARRETAS LTDA | B8: 23.886.769/0001-92 | C8: Rua Mathilde Ferrari Marcon, 450 - Dos Casa, São Bernardo do Campo - SP, 09840-360 | D8: (11) 99176-3052 | E8: contato@primordialcarretas.com.br
A9: Furnax Comercial Importadora | B9: 00.144.257/0001-17 | C9: Rua Maria da Salete L Goncalves, 230 Galpao02, Estancia Sao Francisco 06695-435, SP - Itapevi | D9: (11) 2273-0462 | E9: legalizacao.numes@terra.com.br
A10: VANESSA BERTUCCI ENGENHARIA
A11: ON CONVEYORS ESTEIRAS METALICAS INDUSTRIA E COMERCIO LTDA | B11: 13.518.869/0001-74 | C11: Rua Barbara Heliodora, 281 - UTINGA SANTO ANDRE - SP, 09220-340 | D11: (11) 4451-1470 | E11: c.garcia@on-conveyors.com.br
A12: HENRY PEÇAS COMÉRCIO E SERVIÇOS DE EQUIPAMENTOS HIDRÁULICOS | B12: 12.243.466/0001-05 | C12: Rua Zelia (Ch D Paulista),421 Assuncao São Bernardo do Campo - SP | D12: (11) 2669-7505 | E12: financeiro@henrypecas.com.br
A13: THERMAM LTDA
A14: MAX FIRE
A15: LUSITÂNA

Sheet Controle de Veículos
A1: DATA | B1: FUNCIONÁRIO | C1: VEÍCULO | D1: HORA DE SAÍDA | E1: PREVISÃO DE RETORNO | F1: MOTIVO | G1: STATUS | H1: RETORNO

Sheet Logs
A1: Cliente | B1: Número do Projeto | C1: Observações | D1: Tempo estimado / tempo real de corte | E1: Tempo estimado / tempo real de dobra | F1: Tempo estimado / tempo real de adicionais
A2: LUSITÂNA | B2: 251105cBR | D2: Início: 05/11/2025 14:27

Sheet Avaliações
A1: Avaliador | B1: Tipo | C1: Avaliado | D1: Desempenho | E1: Trabalho em Equipe | F1: Pontualidade | G1: Organizacao | H1: Liderança | I1: Comunicação | J1: Observações

Sheet Tabelas para cálculos
G1: CÁLCULO DE PREÇOS
A2: DADOS DA CHAPA
A3: MATERIAL | B3: DENSIDADE (Kg/m3) | C3: COMPRIMENTO (mm) | D3: LARGURA (mm) | E3: ESPESSURA (mm) | F3: PESO DA CHAPA (Kg) | G3: PREÇO DE COMPRA (R$/KG) | H3: PREÇO DE VENDA (MARK UP 30%) | L3: PREÇO UNITÁRIO (R$) | M3: PREÇO TOTAL (R$) | O3: Preço Kg / material | P3: Peso peça / chapa | Q3: Peso do Lote | R3: Preço Material do Lote | S3: N Trocas de Chapa | T3: TEMPO DE CORTE LOTE (h) | U3: TEMPO DE SETUP (min) | V3: TEMPO DE CORTE LOTE + TEMPO SETUP (h) | W3: HORA DO CORTE (R$/h) | X3: CORTE LOTE (R$) | Y3: Nº DE DOBRAS | Z3: TEMPO DE CADA DOBRA (s) | AA3: Nº TROCAS DE PEÇAS | AB3: TOTAL DOBRA (h) | AC3: HORA DA DOBRA (R$/h) | AD3: TOTAL DOBRA (R$) | AE3: PREÇO UNITÁRIO (R$) | AF3: PREÇO TOTAL (R$)
A4: AÇO CARBONO | B4: 7.86 | C4: 3000 | D4: 1200 | E4: 3 | F4: =C4/1000*D4/1000*E4*B4 -> 84.888 | G4: 7.1 | H4: {=IF(ISERROR(MATCH(E4,'Configurações Máquina de corte'!A:A,0)), INDEX('Configurações Máquina de corte'!F:F, MATCH(E4,'Configurações Máquina de corte'!A:A,1)+1), INDEX('Configurações Máquina de corte'!F:F, MATCH(E4,'Configurações Máquina de corte'!A:A,0)) )} -> 9.585 | K4: AÇO CARBONO | L4: =M4/E12 -> 266.32954 | M4: =I36 -> 266.32954 | O4: =H4 -> 9.585 | P4: =H12 -> 21.222 | Q4: =I12 -> 21.222 | R4: =J12 -> 203.41287 | S4: =D20 -> 1 | T4: =F20 -> 0.016666667 | U4: =G20 -> 4 | V4: =H20 -> 0.083333333 | W4: =B20 -> 275 | X4: =I20 -> 22.916667 | Y4: =D28 -> 4 | Z4: =E28 -> 30 | AA4: =F28 -> 1 | AB4: =H28 -> 0.2 | AC4: =B28 -> 200 | AD4: =I28 -> 40 | AE4: =L4 -> 266.32954 | AF4: =M4 -> 266.32954
A5: ALUMÍNIO | B5: 2.81 | C5: 3000 | D5: 1200 | E5: 3 | F5: =C5/1000*D5/1000*E5*B5 -> 30.348 | G5: 40 | H5: {=IF(ISERROR(MATCH(E5,'Configurações Máquina de corte'!A:A,0)), INDEX('Configurações Máquina de corte'!N:N, MATCH(E5,'Configurações Máquina de corte'!I:I,1)+1), INDEX('Configurações Máquina de corte'!N:N, MATCH(E5,'Configurações Máquina de corte'!I:I,0)) )} -> 56 | K5: ALUMÍNIO | L5: =M5/E13 -> 1782.9394 | M5: =I37 -> 1782.9394 | O5: =H5 -> 56 | P5: =H13 -> 30.348 | Q5: =I13 -> 30.348 | R5: =J13 -> 1699.488 | S5: =D21 -> 1 | T5: =F21 -> 0.018611111 | U5: =G21 -> 4 | V5: =H21 -> 0.085277778 | W5: =B21 -> 275 | X5: =I21 -> 23.451389 | Y5: =D29 -> 4 | Z5: =E29 -> 30 | AA5: =F29 -> 1 | AB5: =H29 -> 0.2 | AC5: =B29 -> 300 | AD5: =I29 -> 60 | AE5: =L5 -> 1782.9394 | AF5: =M5 -> 1782.9394
A6: INOX 200 OU 300 | B6: 7.86 | C6: 3000 | D6: 1200 | E6: 3 | F6: =C6/1000*D6/1000*E6*B6 -> 84.888 | G6: 26 | H6: {=IF(ISERROR(MATCH(E6,'Configurações Máquina de corte'!A:A,0)), INDEX('Configurações Máquina de corte'!N:N, MATCH(E6,'Configurações Máquina de corte'!I:I,1)+1), INDEX('Configurações Máquina de corte'!N:N, MATCH(E6,'Configurações Máquina de corte'!I:I,0)) )} -> 56 | K6: INOX 200 OU 300 | L6: =M6/E14 -> 195.92511 | M6: =I38 -> 195.92511 | O6: =H6 -> 56 | P6: =H14 -> 3.144 | Q6: =I14 -> 3.144 | R6: =J14 -> 176.064 | S6: =D22 -> 1 | T6: =F22 -> 0.0055555556 | U6: =G22 -> 4 | V6: =H22 -> 0.072222222 | W6: =B22 -> 275 | X6: =I22 -> 19.861111 | Y6: =D30 -> 0 | Z6: =E30 -> 0 | AA6: =F30 -> 1 | AB6: =H30 -> 0 | AC6: =B30 -> 200 | AD6: =I30 -> 0 | AE6: =L6 -> 195.92511 | AF6: =M6 -> 195.92511
A7: INOX 400 | B7: 7.86 | C7: 3000 | D7: 1200 | E7: 2 | F7: 56.592 | G7: 40 | H7: {=IF(ISERROR(MATCH(E7,'Configurações Máquina de corte'!A:A,0)), INDEX('Configurações Máquina de corte'!N:N, MATCH(E7,'Configurações Máquina de corte'!I:I,1)+1), INDEX('Configurações Máquina de corte'!N:N, MATCH(E7,'Configurações Máquina de corte'!I:I,0)) )} -> 53 | K7: INOX 400 | L7: =M7/E15 -> 30.177093 | M7: =I39 -> 3017.7093 | O7: 0 | P7: 0.56592 | Q7: =I15 -> 56.592 | R7: =J15 -> 2999.376 | S7: =D23 -> 1 | T7: =F23 -> 0 | U7: =G23 -> 4 | V7: =H23 -> 0.066666667 | W7: =B23 -> 275 | X7: =I23 -> 18.333333 | Y7: =D31 -> 1 | Z7: =E31 -> 0 | AA7: =F31 -> 100 | AB7: =H31 -> 0 | AC7: =B31 -> 200 | AD7: =I31 -> 0 | AE7: =L7 -> 30.177093 | AF7: =M7 -> 3017.7093
A8: LATÃO | B8: 8.7 | C8: 3000 | D8: 1200 | E8: 2 | F8: =C8/1000*D8/1000*E8*B8 -> 62.64 | G8: 35 | H8: {=IF(ISERROR(MATCH(E8,'Configurações Máquina de corte'!A:A,0)), INDEX('Configurações Máquina de corte'!N:N, MATCH(E8,'Configurações Máquina de corte'!I:I,1)+1), INDEX('Configurações Máquina de corte'!N:N, MATCH(E8,'Configurações Máquina de corte'!I:I,0)) )} -> 53 | K8: LATÃO | L8: =M8/E16 -> 553.32 | M8: =I40 -> 553.32 | O8: =H8 -> 53 | P8: =H16 -> 10.44 | Q8: =I16 -> 10.44 | R8: =J16 -> 553.32 | S8: =D24 -> 1 | T8: =F24 -> 0 | U8: =G24 -> 0 | V8: =H24 -> 0 | W8: =B24 -> FALSE | X8: =I24 -> 0 | Y8: =D32 -> 1 | Z8: =E32 -> 0 | AA8: =F32 -> 1 | AB8: =H32 -> 0 | AC8: =B32 -> 200 | AD8: =I32 -> 0 | AE8: =L8 -> 553.32 | AF8: =M8 -> 553.32
A9: COBRE | B9: 8.96 | C9: 3000 | D9: 1200 | E9: 2 | F9: =C9/1000*D9/1000*E9*B9 -> 64.512 | G9: 52 | H9: {=IF(ISERROR(MATCH(E9,'Configurações Máquina de corte'!A:A,0)), INDEX('Configurações Máquina de corte'!N:N, MATCH(E9,'Configurações Máquina de corte'!I:I,1)+1), INDEX('Configurações Máquina de corte'!N:N, MATCH(E9,'Configurações Máquina de corte'!I:I,0)) )} -> 53 | K9: COBRE | L9: =M9/E17 -> 569.856 | M9: =I41 -> 569.856 | O9: =H9 -> 53 | P9: =H17 -> 10.752 | Q9: =I17 -> 10.752 | R9: =J17 -> 569.856 | S9: =D25 -> 1 | T9: =F25 -> 0 | U9: =G25 -> 0 | V9: =H25 -> 0 | W9: =B25 -> FALSE | X9: =I25 -> 0 | Y9: =D33 -> 1 | Z9: =E33 -> 0 | AA9: =F33 -> 1 | AB9: =H33 -> 0 | AC9: =B33 -> 200 | AD9: =I33 -> 0 | AE9: =L9 -> 569.856 | AF9: =M9 -> 569.856
A10: DADOS DA PEÇA
A11: MATERIAL | B11: COMPRIMENTO (mm) | C11: LARGURA (mm) | D11: PERÍMETRO DA PEÇA (mm) | E11: Nº DE PEÇAS DO LOTE | F11: Nº PEÇAS QUE CABEM EM UMA CHAPA* | G11: MASSA DE 1 BLANK (Kg) | H11: PESO DA PEÇA POR CHAPA (Kg) | I11: PESO DO LOTE (Kg) | J11: PREÇO DE VENDA DO MATERIAL DO LOTE
A12: AÇO CARBONO | B12: 700 | C12: 705 | D12: 30 | E12: 1 | F12: 4 | G12: =(B12/1000 *C12/1000 *E4 * B4) -> 11.63673 | H12: =F4/F12 -> 21.222 | I12: =H12*E12 -> 21.222 | J12: =H4*I12 -> 203.41287
A13: ALUMÍNIO | B13: 700 | C13: 705 | D13: =B13*2 + C13*2 -> 2810 | E13: 1 | F13: 1 | G13: =(B13/1000 *C13/1000 *E5 * B5) -> 4.160205 | H13: =F5/F13 -> 30.348 | I13: =H13*E13 -> 30.348 | J13: =H5*I13 -> 1699.488
A14: INOX 200 OU 300 | B14: 1295 | C14: 82 | D14: =B14*2 + C14*2 -> 2754 | E14: 1 | F14: 27 | G14: =(B14/1000 *C14/1000 *E6 * B6) -> 2.5039602 | H14: =F6/F14 -> 3.144 | I14: =H14*E14 -> 3.144 | J14: =H6*I14 -> 176.064
A15: INOX 400 | B15: 65 | C15: 45 | D15: =B15*2 + C15*2 -> 220 | E15: 100 | F15: 100 | G15: =(B15/1000 *C15/1000 *E7 * B7) -> 0.045981 | H15: =F7/F15 -> 0.56592 | I15: =H15*E15 -> 56.592 | J15: =H7*I15 -> 2999.376
A16: LATÃO | B16: 1000 | C16: 1000 | D16: =B16*2 + C16*2 -> 4000 | E16: 1 | F16: 6 | G16: =(B16/1000 *C16/1000 *E8 * B8) -> 17.4 | H16: =F8/F16 -> 10.44 | I16: =H16*E16 -> 10.44 | J16: =H8*I16 -> 553.32
A17: COBRE | B17: 1000 | C17: 1000 | D17: =B17*2 + C17*2 -> 4000 | E17: 1 | F17: 6 | G17: =(B17/1000 *C17/1000 *E9 * B9) -> 17.92 | H17: =F9/F17 -> 10.752 | I17: =H17*E17 -> 10.752 | J17: =H9*I17 -> 569.856
A18: DADOS DO CORTE
A19: MATERIAL | B19: PREÇO DA HORA DO CORTE (R$/h) | C19: VALOR MÍNIMO P/ PEDIDO | D19: Nº TROCAS DE CHAPA | E19: TEMPO DE CORTE UMA PEÇA (s) | F19: TEMPO DE CORTE LOTE (h) | G19: TEMPO DE SETUP (min) | H19: TEMPO DE CORTE LOTE + TEMPO SETUP (h) | I19: PREÇO DE CORTE LOTE (R$)
A20: AÇO CARBONO | B20: {=IFERROR( IF(A20="AÇO CARBONO", INDEX('Configurações Máquina de corte'!E:E, IF(ISERROR(MATCH(E4,'Configurações Máquina de corte'!A:A,0)), MATCH(E4,'Configurações Máquina de corte'!A:A,1)+1, MATCH(E4,'Configurações Máquina de corte'!A:A,0) ) ), IF(A20="ALUMÍNIO", INDEX('Configurações Máquina de corte'!M:M, IF(ISERROR(MATCH(E5,'Configurações Máquina de corte'!I:I,0)), MATCH(E5,'Configurações Máquina de corte'!I:I,1)+1, MATCH(E5,'Configurações Máquina de corte'!I:I,0) ) ), IF(OR(A20="INOX",A20="INOX 200 OU 300",A20="INOX 400"), INDEX('Configurações Máquina de corte'!U:U, IF(ISERROR(MATCH(E6,'Configurações Máquina de corte'!Q:Q,0)), MATCH(E6,'Configurações Máquina de corte'!Q:Q,1)+1, MATCH(E6,'Configurações Máquina de corte'!Q:Q,0) ) ) ))),"")} -> 275 | C20: {=IFERROR( IF(A20="AÇO CARBONO", INDEX('Configurações Máquina de corte'!E:E, IF(ISERROR(MATCH(E4,'Configurações Máquina de corte'!A:A,0)), MATCH(E4,'Configurações Máquina de corte'!A:A,1)+1, MATCH(E4,'Configurações Máquina de corte'!A:A,0) ) ), IF(A20="ALUMÍNIO", INDEX('Configurações Máquina de corte'!M:M, IF(ISERROR(MATCH(E5,'Configurações Máquina de corte'!I:I,0)), MATCH(E5,'Configurações Máquina de corte'!I:I,1)+1, MATCH(E5,'Configurações Máquina de corte'!I:I,0) ) ), IF(OR(A20="INOX",A20="INOX 200 OU 300",A20="INOX 400"), INDEX('Configurações Máquina de corte'!U:U, IF(ISERROR(MATCH(E6,'Configurações Máquina de corte'!Q:Q,0)), MATCH(E6,'Configurações Máquina de corte'!Q:Q,1)+1, MATCH(E6,'Configurações Máquina de corte'!Q:Q,0) ) ) ))),"")} -> 275 | D20: =ROUNDUP(E12/F12,0) -> 1 | E20: 60 | F20: =(E20 * E12)/3600 -> 0.016666667 | G20: {=IFERROR( D20 * IF(A20="AÇO CARBONO", INDEX('Configurações Máquina de corte'!B:B, IF(ISERROR(MATCH(E4,'Configurações Máquina de corte'!A:A,0)), MATCH(E4,'Configurações Máquina de corte'!A:A,1)+1, MATCH(E4,'Configurações Máquina de corte'!A:A,0) ) ), IF(A20="ALUMÍNIO", INDEX('Configurações Máquina de corte'!J:J, IF(ISERROR(MATCH(E5,'Configurações Máquina de corte'!I:I,0)), MATCH(E5,'Configurações Máquina de corte'!I:I,1)+1, MATCH(E5,'Configurações Máquina de corte'!I:I,0) ) ), IF(OR(A20="INOX",A20="INOX 200 OU 300",A20="INOX 400"), INDEX('Configurações Máquina de corte'!R:R, IF(ISERROR(MATCH(E6,'Configurações Máquina de corte'!Q:Q,0)), MATCH(E6,'Configurações Máquina de corte'!Q:Q,1)+1, MATCH(E6,'Configurações Máquina de corte'!Q:Q,0) ) ), 0))), "Verifique Material/Espessura")} -> 4 | H20: =F20 + (G20/60) -> 0.083333333 | I20: =B20*H20 -> 22.916667
A21: ALUMÍNIO | B21: {=IFERROR( IF(A21="AÇO CARBONO", INDEX('Configurações Máquina de corte'!E:E, IF(ISERROR(MATCH(E5,'Configurações Máquina de corte'!A:A,0)), MATCH(E5,'Configurações Máquina de corte'!A:A,1)+1, MATCH(E5,'Configurações Máquina de corte'!A:A,0) ) ), IF(A21="ALUMÍNIO", INDEX('Configurações Máquina de corte'!M:M, IF(ISERROR(MATCH(E6,'Configurações Máquina de corte'!I:I,0)), MATCH(E6,'Configurações Máquina de corte'!I:I,1)+1, MATCH(E6,'Configurações Máquina de corte'!I:I,0) ) ), IF(OR(A21="INOX",A21="INOX 200 OU 300",A21="INOX 400"), INDEX('Configurações Máquina de corte'!U:U, IF(ISERROR(MATCH(E7,'Configurações Máquina de corte'!Q:Q,0)), MATCH(E7,'Configurações Máquina de corte'!Q:Q,1)+1, MATCH(E7,'Configurações Máquina de corte'!Q:Q,0) ) ) ))),"")} -> 275 | C21: {=IFERROR( IF(A21="AÇO CARBONO", INDEX('Configurações Máquina de corte'!E:E, IF(ISERROR(MATCH(E5,'Configurações Máquina de corte'!A:A,0)), MATCH(E5,'Configurações Máquina de corte'!A:A,1)+1, MATCH(E5,'Configurações Máquina de corte'!A:A,0) ) ), IF(A21="ALUMÍNIO", INDEX('Configurações Máquina de corte'!M:M, IF(ISERROR(MATCH(E6,'Configurações Máquina de corte'!I:I,0)), MATCH(E6,'Configurações Máquina de corte'!I:I,1)+1, MATCH(E6,'Configurações Máquina de corte'!I:I,0) ) ), IF(OR(A21="INOX",A21="INOX 200 OU 300",A21="INOX 400"), INDEX('Configurações Máquina de corte'!U:U, IF(ISERROR(MATCH(E7,'Configurações Máquina de corte'!Q:Q,0)), MATCH(E7,'Configurações Máquina de corte'!Q:Q,1)+1, MATCH(E7,'Configurações Máquina de corte'!Q:Q,0) ) ) ))),"")} -> 275 | D21: =ROUNDUP(E13/F13,0) -> 1 | E21: 67 | F21: =(E21 * E13)/3600 -> 0.018611111 | G21: {=IFERROR( D21 * IF(A21="AÇO CARBONO", INDEX('Configurações Máquina de corte'!B:B, IF(ISERROR(MATCH(E5,'Configurações Máquina de corte'!A:A,0)), MATCH(E5,'Configurações Máquina de corte'!A:A,1)+1, MATCH(E5,'Configurações Máquina de corte'!A:A,0) ) ), IF(A21="ALUMÍNIO", INDEX('Configurações Máquina de corte'!J:J, IF(ISERROR(MATCH(E6,'Configurações Máquina de corte'!I:I,0)), MATCH(E6,'Configurações Máquina de corte'!I:I,1)+1, MATCH(E6,'Configurações Máquina de corte'!I:I,0) ) ), IF(OR(A21="INOX",A21="INOX 200 OU 300",A21="INOX 400"), INDEX('Configurações Máquina de corte'!R:R, IF(ISERROR(MATCH(E7,'Configurações Máquina de corte'!Q:Q,0)), MATCH(E7,'Configurações Máquina de corte'!Q:Q,1)+1, MATCH(E7,'Configurações Máquina de corte'!Q:Q,0) ) ), 0))), "Verifique Material/Espessura")} -> 4 | H21: =F21 + (G21/60) -> 0.085277778 | I21: =B21*H21 -> 23.451389
A22: INOX 200 OU 300 | B22: {=IFERROR( IF(A22="AÇO CARBONO", INDEX('Configurações Máquina de corte'!E:E, IF(ISERROR(MATCH(E6,'Configurações Máquina de corte'!A:A,0)), MATCH(E6,'Configurações Máquina de corte'!A:A,1)+1, MATCH(E6,'Configurações Máquina de corte'!A:A,0) ) ), IF(A22="ALUMÍNIO", INDEX('Configurações Máquina de corte'!M:M, IF(ISERROR(MATCH(E7,'Configurações Máquina de corte'!I:I,0)), MATCH(E7,'Configurações Máquina de corte'!I:I,1)+1, MATCH(E7,'Configurações Máquina de corte'!I:I,0) ) ), IF(OR(A22="INOX",A22="INOX 200 OU 300",A22="INOX 400"), INDEX('Configurações Máquina de corte'!U:U, IF(ISERROR(MATCH(E8,'Configurações Máquina de corte'!Q:Q,0)), MATCH(E8,'Configurações Máquina de corte'!Q:Q,1)+1, MATCH(E8,'Configurações Máquina de corte'!Q:Q,0) ) ) ))),"")} -> 275 | C22: {=IFERROR( IF(A22="AÇO CARBONO", INDEX('Configurações Máquina de corte'!E:E, IF(ISERROR(MATCH(E6,'Configurações Máquina de corte'!A:A,0)), MATCH(E6,'Configurações Máquina de corte'!A:A,1)+1, MATCH(E6,'Configurações Máquina de corte'!A:A,0) ) ), IF(A22="ALUMÍNIO", INDEX('Configurações Máquina de corte'!M:M, IF(ISERROR(MATCH(E7,'Configurações Máquina de corte'!I:I,0)), MATCH(E7,'Configurações Máquina de corte'!I:I,1)+1, MATCH(E7,'Configurações Máquina de corte'!I:I,0) ) ), IF(OR(A22="INOX",A22="INOX 200 OU 300",A22="INOX 400"), INDEX('Configurações Máquina de corte'!U:U, IF(ISERROR(MATCH(E8,'Configurações Máquina de corte'!Q:Q,0)), MATCH(E8,'Configurações Máquina de corte'!Q:Q,1)+1, MATCH(E8,'Configurações Máquina de corte'!Q:Q,0) ) ) ))),"")} -> 275 | D22: =ROUNDUP(E14/F14,0) -> 1 | E22: 20 | F22: =(E22 * E14)/3600 -> 0.0055555556 | G22: {=IFERROR( D22 * IF(A22="AÇO CARBONO", INDEX('Configurações Máquina de corte'!B:B, IF(ISERROR(MATCH(E6,'Configurações Máquina de corte'!A:A,0)), MATCH(E6,'Configurações Máquina de corte'!A:A,1)+1, MATCH(E6,'Configurações Máquina de corte'!A:A,0) ) ), IF(A22="ALUMÍNIO", INDEX('Configurações Máquina de corte'!J:J, IF(ISERROR(MATCH(E7,'Configurações Máquina de corte'!I:I,0)), MATCH(E7,'Configurações Máquina de corte'!I:I,1)+1, MATCH(E7,'Configurações Máquina de corte'!I:I,0) ) ), IF(OR(A22="INOX",A22="INOX 200 OU 300",A22="INOX 400"), INDEX('Configurações Máquina de corte'!R:R, IF(ISERROR(MATCH(E8,'Configurações Máquina de corte'!Q:Q,0)), MATCH(E8,'Configurações Máquina de corte'!Q:Q,1)+1, MATCH(E8,'Configurações Máquina de corte'!Q:Q,0) ) ), 0))), "Verifique Material/Espessura")} -> 4 | H22: =F22 + (G22/60) -> 0.072222222 | I22: =B22*H22 -> 19.861111
A23: INOX 400 | B23: {=IFERROR( IF(A23="AÇO CARBONO", INDEX('Configurações Máquina de corte'!E:E, IF(ISERROR(MATCH(E7,'Configurações Máquina de corte'!A:A,0)), MATCH(E7,'Configurações Máquina de corte'!A:A,1)+1, MATCH(E7,'Configurações Máquina de corte'!A:A,0) ) ), IF(A23="ALUMÍNIO", INDEX('Configurações Máquina de corte'!M:M, IF(ISERROR(MATCH(E8,'Configurações Máquina de corte'!I:I,0)), MATCH(E8,'Configurações Máquina de corte'!I:I,1)+1, MATCH(E8,'Configurações Máquina de corte'!I:I,0) ) ), IF(OR(A23="INOX",A23="INOX 200 OU 300",A23="INOX 400"), INDEX('Configurações Máquina de corte'!U:U, IF(ISERROR(MATCH(E9,'Configurações Máquina de corte'!Q:Q,0)), MATCH(E9,'Configurações Máquina de corte'!Q:Q,1)+1, MATCH(E9,'Configurações Máquina de corte'!Q:Q,0) ) ) ))),"")} -> 275 | C23: {=IFERROR( IF(A23="AÇO CARBONO", INDEX('Configurações Máquina de corte'!E:E, IF(ISERROR(MATCH(E7,'Configurações Máquina de corte'!A:A,0)), MATCH(E7,'Configurações Máquina de corte'!A:A,1)+1, MATCH(E7,'Configurações Máquina de corte'!A:A,0) ) ), IF(A23="ALUMÍNIO", INDEX('Configurações Máquina de corte'!M:M, IF(ISERROR(MATCH(E8,'Configurações Máquina de corte'!I:I,0)), MATCH(E8,'Configurações Máquina de corte'!I:I,1)+1, MATCH(E8,'Configurações Máquina de corte'!I:I,0) ) ), IF(OR(A23="INOX",A23="INOX 200 OU 300",A23="INOX 400"), INDEX('Configurações Máquina de corte'!U:U, IF(ISERROR(MATCH(E9,'Configurações Máquina de corte'!Q:Q,0)), MATCH(E9,'Configurações Máquina de corte'!Q:Q,1)+1, MATCH(E9,'Configurações Máquina de corte'!Q:Q,0) ) ) ))),"")} -> 275 | D23: =ROUNDUP(E15/F15,0) -> 1 | E23: 0 | F23: =(E23 * E15)/3600 -> 0 | G23: {=IFERROR( D23 * IF(A23="AÇO CARBONO", INDEX('Configurações Máquina de corte'!B:B, IF(ISERROR(MATCH(E7,'Configurações Máquina de corte'!A:A,0)), MATCH(E7,'Configurações Máquina de corte'!A:A,1)+1, MATCH(E7,'Configurações Máquina de corte'!A:A,0) ) ), IF(A23="ALUMÍNIO", INDEX('Configurações Máquina de corte'!J:J, IF(ISERROR(MATCH(E8,'Configurações Máquina de corte'!I:I,0)), MATCH(E8,'Configurações Máquina de corte'!I:I,1)+1, MATCH(E8,'Configurações Máquina de corte'!I:I,0) ) ), IF(OR(A23="INOX",A23="INOX 200 OU 300",A23="INOX 400"), INDEX('Configurações Máquina de corte'!R:R, IF(ISERROR(MATCH(E9,'Configurações Máquina de corte'!Q:Q,0)), MATCH(E9,'Configurações Máquina de corte'!Q:Q,1)+1, MATCH(E9,'Configurações Máquina de corte'!Q:Q,0) ) ), 0))), "Verifique Material/Espessura")} -> 4 | H23: =F23 + (G23/60) -> 0.066666667 | I23: =B23*H23 -> 18.333333
A24: LATÃO | B24: {=IFERROR( IF(A24="AÇO CARBONO", INDEX('Configurações Máquina de corte'!E:E, IF(ISERROR(MATCH(E8,'Configurações Máquina de corte'!A:A,0)), MATCH(E8,'Configurações Máquina de corte'!A:A,1)+1, MATCH(E8,'Configurações Máquina de corte'!A:A,0) ) ), IF(A24="ALUMÍNIO", INDEX('Configurações Máquina de corte'!M:M, IF(ISERROR(MATCH(E9,'Configurações Máquina de corte'!I:I,0)), MATCH(E9,'Configurações Máquina de corte'!I:I,1)+1, MATCH(E9,'Configurações Máquina de corte'!I:I,0) ) ), IF(OR(A24="INOX",A24="INOX 200 OU 300",A24="INOX400"), INDEX('Configurações Máquina de corte'!U:U, IF(ISERROR(MATCH(E10,'Configurações Máquina de corte'!Q:Q,0)), MATCH(E10,'Configurações Máquina de corte'!Q:Q,1)+1, MATCH(E10,'Configurações Máquina de corte'!Q:Q,0) ) ) ))),"")} -> FALSE | C24: {=IFERROR( IF(A24="AÇO CARBONO", INDEX('Configurações Máquina de corte'!E:E, IF(ISERROR(MATCH(E8,'Configurações Máquina de corte'!A:A,0)), MATCH(E8,'Configurações Máquina de corte'!A:A,1)+1, MATCH(E8,'Configurações Máquina de corte'!A:A,0) ) ), IF(A24="ALUMÍNIO", INDEX('Configurações Máquina de corte'!M:M, IF(ISERROR(MATCH(E9,'Configurações Máquina de corte'!I:I,0)), MATCH(E9,'Configurações Máquina de corte'!I:I,1)+1, MATCH(E9,'Configurações Máquina de corte'!I:I,0) ) ), IF(OR(A24="INOX",A24="INOX 200 OU 300",A24="INOX 400"), INDEX('Configurações Máquina de corte'!U:U, IF(ISERROR(MATCH(E10,'Configurações Máquina de corte'!Q:Q,0)), MATCH(E10,'Configurações Máquina de corte'!Q:Q,1)+1, MATCH(E10,'Configurações Máquina de corte'!Q:Q,0) ) ) ))),"")} -> FALSE | D24: =ROUNDUP(E16/F16,0) -> 1 | E24: 0 | F24: =(E24 * E16)/3600 -> 0 | G24: {=IFERROR( D24 * IF(A24="AÇO CARBONO", INDEX('Configurações Máquina de corte'!B:B, IF(ISERROR(MATCH(E8,'Configurações Máquina de corte'!A:A,0)), MATCH(E8,'Configurações Máquina de corte'!A:A,1)+1, MATCH(E8,'Configurações Máquina de corte'!A:A,0) ) ), IF(A24="ALUMÍNIO", INDEX('Configurações Máquina de corte'!J:J, IF(ISERROR(MATCH(E9,'Configurações Máquina de corte'!I:I,0)), MATCH(E9,'Configurações Máquina de corte'!I:I,1)+1, MATCH(E9,'Configurações Máquina de corte'!I:I,0) ) ), IF(OR(A24="INOX",A24="INOX 200 OU 300",A24="INOX 400"), INDEX('Configurações Máquina de corte'!R:R, IF(ISERROR(MATCH(E10,'Configurações Máquina de corte'!Q:Q,0)), MATCH(E10,'Configurações Máquina de corte'!Q:Q,1)+1, MATCH(E10,'Configurações Máquina de corte'!Q:Q,0) ) ), 0))), "Verifique Material/Espessura")} -> 0 | H24: =F24 + (G24/60) -> 0 | I24: =B24*H24 -> 0
A25: COBRE | B25: {=IFERROR( IF(A25="AÇO CARBONO", INDEX('Configurações Máquina de corte'!E:E, IF(ISERROR(MATCH(E9,'Configurações Máquina de corte'!A:A,0)), MATCH(E9,'Configurações Máquina de corte'!A:A,1)+1, MATCH(E9,'Configurações Máquina de corte'!A:A,0) ) ), IF(A25="ALUMÍNIO", INDEX('Configurações Máquina de corte'!M:M, IF(ISERROR(MATCH(E10,'Configurações Máquina de corte'!I:I,0)), MATCH(E10,'Configurações Máquina de corte'!I:I,1)+1, MATCH(E10,'Configurações Máquina de corte'!I:I,0) ) ), IF(OR(A25="INOX",A25="INOX 200 OU 300",A25="INOX400"), INDEX('Configurações Máquina de corte'!U:U, IF(ISERROR(MATCH(E11,'Configurações Máquina de corte'!Q:Q,0)), MATCH(E11,'Configurações Máquina de corte'!Q:Q,1)+1, MATCH(E11,'Configurações Máquina de corte'!Q:Q,0) ) ) ))),"")} -> FALSE | C25: {=IFERROR( IF(A25="AÇO CARBONO", INDEX('Configurações Máquina de corte'!E:E, IF(ISERROR(MATCH(E9,'Configurações Máquina de corte'!A:A,0)), MATCH(E9,'Configurações Máquina de corte'!A:A,1)+1, MATCH(E9,'Configurações Máquina de corte'!A:A,0) ) ), IF(A25="ALUMÍNIO", INDEX('Configurações Máquina de corte'!M:M, IF(ISERROR(MATCH(E10,'Configurações Máquina de corte'!I:I,0)), MATCH(E10,'Configurações Máquina de corte'!I:I,1)+1, MATCH(E10,'Configurações Máquina de corte'!I:I,0) ) ), IF(OR(A25="INOX",A25="INOX 200 OU 300",A25="INOX 400"), INDEX('Configurações Máquina de corte'!U:U, IF(ISERROR(MATCH(E11,'Configurações Máquina de corte'!Q:Q,0)), MATCH(E11,'Configurações Máquina de corte'!Q:Q,1)+1, MATCH(E11,'Configurações Máquina de corte'!Q:Q,0) ) ) ))),"")} -> FALSE | D25: =ROUNDUP(E17/F17,0) -> 1 | E25: 0 | F25: =(E25 * E17)/3600 -> 0 | G25: {=IFERROR( D25 * IF(A25="AÇO CARBONO", INDEX('Configurações Máquina de corte'!B:B, IF(ISERROR(MATCH(E9,'Configurações Máquina de corte'!A:A,0)), MATCH(E9,'Configurações Máquina de corte'!A:A,1)+1, MATCH(E9,'Configurações Máquina de corte'!A:A,0) ) ), IF(A25="ALUMÍNIO", INDEX('Configurações Máquina de corte'!J:J, IF(ISERROR(MATCH(E10,'Configurações Máquina de corte'!I:I,0)), MATCH(E10,'Configurações Máquina de corte'!I:I,1)+1, MATCH(E10,'Configurações Máquina de corte'!I:I,0) ) ), IF(OR(A25="INOX",A25="INOX 200 OU 300",A25="INOX 400"), INDEX('Configurações Máquina de corte'!R:R, IF(ISERROR(MATCH(E11,'Configurações Máquina de corte'!Q:Q,0)), MATCH(E11,'Configurações Máquina de corte'!Q:Q,1)+1, MATCH(E11,'Configurações Máquina de corte'!Q:Q,0) ) ), 0))), "Verifique Material/Espessura")} -> 0 | H25: =F25 + (G25/60) -> 0 | I25: =B25*H25 -> 0
A26: DADOS DA DOBRA
A27: MATERIAL | B27: PREÇO DA HORA DA DOBRA (R$/h) | C27: VALOR MÍNIMO P/ PEDIDO | D27: Nº DE DOBRAS | E27: TEMPO DE CADA DOBRA (s) | F27: Nº TROCAS DE PEÇAS | G27: TEMPO DE SETUP (min) | H27: TEMPO TOTAL DOBRA (h) | I27: PREÇO TOTAL DOBRA (R$)
A28: AÇO CARBONO | B28: 200 | C28: =B28*0.5 -> 100 | D28: 4 | E28: 30 | F28: =E12 -> 1 | G28: 10 | H28: =(D28*E28)/3600 +(F28*G28)/60 -> 0.2 | I28: =H28*B28 -> 40
A29: ALUMÍNIO | B29: 300 | C29: =B29*0.5 -> 150 | D29: 4 | E29: 30 | F29: =E13 -> 1 | G29: 10 | H29: =(D29*E29)/3600 +(F29*G29)/60 -> 0.2 | I29: =H29*B29 -> 60
A30: INOX 200 OU 300 | B30: 200 | C30: =B30*0.5 -> 100 | D30: 0 | E30: 0 | F30: =E14 -> 1 | G30: 0 | H30: =(D30*E30)/3600 +(F30*G30)/60 -> 0 | I30: =H30*B30 -> 0
A31: INOX 400 | B31: 200 | C31: =B31*0.5 -> 100 | D31: 1 | E31: 0 | F31: =E15 -> 100 | G31: 0 | H31: =(D31*E31)/3600 +(F31*G31)/60 -> 0 | I31: =H31*B31 -> 0
A32: LATÃO | B32: 200 | C32: =B32*0.5 -> 100 | D32: 1 | E32: 0 | F32: =E16 -> 1 | G32: 0 | H32: =(D32*E32)/3600 +(F32*G32)/60 -> 0 | I32: =H32*B32 -> 0
A33: COBRE | B33: 200 | C33: =B33*0.5 -> 100 | D33: 1 | E33: 0 | F33: =E17 -> 1 | G33: 0 | H33: =(D33*E33)/3600 +(F33*G33)/60 -> 0 | I33: =H33*B33 -> 0
A34: PREÇO FINAL
A35: MATERIAL | B35: PREÇO UNITÁRIO DO CORTE (R$) | C35: PREÇO UNITÁRIO DA DOBRA (R$) | D35: PREÇO UNITÁRIO DO MATERIAL (R$) | E35: PREÇO UNITÁRIO CORTE + MATERIAL + DOBRA (R$) | F35: PREÇO DE CORTE LOTE (R$) | G35: PREÇO DE DOBRA DO LOTE (R$) | H35: PREÇO DE VENDA DO MATERIAL DO LOTE | I35: PREÇO TOTAL CORTE + MATERIAL + DOBRA (R$)
A36: AÇO CARBONO | B36: =F36/E12 -> 22.916667 | C36: =I28/E12 -> 40 | D36: =H36/E12 -> 203.41287 | E36: =B36+C36+D36 -> 266.32954 | F36: =I20 -> 22.916667 | G36: =I28 -> 40 | H36: =J12 -> 203.41287 | I36: =H36+G36+F36 -> 266.32954
A37: ALUMÍNIO | B37: =F37/E13 -> 23.451389 | C37: =I29/E13 -> 60 | D37: =H37/E13 -> 1699.488 | E37: =B37+C37+D37 -> 1782.9394 | F37: =I21 -> 23.451389 | G37: =I29 -> 60 | H37: =J13 -> 1699.488 | I37: =H37+G37+F37 -> 1782.9394
A38: INOX 200 OU 300 | B38: =F38/E14 -> 19.861111 | C38: =I30/E14 -> 0 | D38: =H38/E14 -> 176.064 | E38: =B38+C38+D38 -> 195.92511 | F38: =I22 -> 19.861111 | G38: =I30 -> 0 | H38: =J14 -> 176.064 | I38: =H38+G38+F38 -> 195.92511
A39: INOX 400 | B39: =F39/E15 -> 0.18333333 | C39: =I31/E15 -> 0 | D39: =H39/E15 -> 29.99376 | E39: =B39+C39+D39 -> 30.177093 | F39: =I23 -> 18.333333 | G39: =I31 -> 0 | H39: =J15 -> 2999.376 | I39: =H39+G39+F39 -> 3017.7093
A40: LATÃO | B40: =F40/E16 -> 0 | C40: =I32/E16 -> 0 | D40: =H40/E16 -> 553.32 | E40: =B40+C40+D40 -> 553.32 | F40: =I24 -> 0 | G40: =I32 -> 0 | H40: =J16 -> 553.32 | I40: =H40+G40+F40 -> 553.32
...

Sheet Configurações Máquina de corte
A1: AÇO CARBONO | J1: ALUMÍNIO | R1: INOX 200 OU 300
A2: ESPESSURA chapa (mm) | B2: TEMPO PARA TROCA DE CHAPAS (min) | C2: TEMPO PARA CADA ENTRADA (furos) (s) | D2: VELOCIDADE de CORTE (mm/s) | E2: PREÇO DA HORA DO CORTE (R$) | F2: PREÇO DE VENDA (MARK UP 30%) | I2: ESPESSURA chapa (mm) | J2: TEMPO PARA TROCA DE CHAPAS (min) | K2: TEMPO PARA CADA ENTRADA (furos) (s) | L2: VELOCIDADE de CORTE (mm/s) | M2: PREÇO DA HORA DO CORTE (R$) | N2: PREÇO DE VENDA (MARK UP 30%) | Q2: ESPESSURA chapa (mm) | R2: TEMPO PARA TROCA DE CHAPAS (min) | S2: TEMPO PARA CADA ENTRADA (furos) (s) | T2: VELOCIDADE de CORTE (mm/s) | U2: PREÇO DA HORA DO CORTE (R$) | V2: PREÇO DE VENDA (MARK UP 30%)
